Workbook

Sheet inputs
A1: Face Amount | B1: 100000
A2: Term | B2: 10
A3: Interest Rate | B3: 0.05 | C3: 0.03 | D3: 0.07
A5: Issue Ages | B5: 30
B6: 40
B7: 50
B8: 60

Sheet Mortality_Table
A1: Age | B1: qx | C1: px
A2: 30 | B2: 0.000315 | C2: =1-B2 -> 0.999685
A3: 31 | B3: 0.000327 | C3: =1-B3 -> 0.999673
A4: 32 | B4: 0.000341 | C4: =1-B4 -> 0.999659
A5: 33 | B5: 0.000356 | C5: =1-B5 -> 0.999644
A6: 34 | B6: 0.000372 | C6: =1-B6 -> 0.999628
A7: 35 | B7: 0.000391 | C7: =1-B7 -> 0.999609
A8: 36 | B8: 0.000412 | C8: =1-B8 -> 0.999588
A9: 37 | B9: 0.000436 | C9: =1-B9 -> 0.999564
A10: 38 | B10: 0.000463 | C10: =1-B10 -> 0.999537
A11: 39 | B11: 0.000493 | C11: =1-B11 -> 0.999507
A12: 40 | B12: 0.000527 | C12: =1-B12 -> 0.999473
A13: 41 | B13: 0.000565 | C13: =1-B13 -> 0.999435
... A41: 69 | B41: 0.009294 | C41: =1-B41 -> 0.990706

Sheet Pricing
A1: Selected Issue Age | B1: 60
A2: Face Amount | B2: =inputs!B1 -> 100000
A3: Term | B3: =inputs!B2 -> 10
A4: Interest Rate | B4: =inputs!B3 -> 0.05
A7: Policy Year | B7: Attained Age | C7: qx | D7: px | E7: Survival to Start | F7: Discount Factor | G7: EPV Contribution
A8: 1 | B8: =$B$1+A8-1 -> 60 | C8: =_xlfn.XLOOKUP(B8,Mortality_Table!$A:$A,Mortality_Table!$B:$B) -> 0.003398 | D8: =1-C8 -> 0.996602 | E8: =1 -> 1 | F8: =1/(1+$B$4)^A8 -> 0.95238095 | G8: =$B$2*E8*C8*F8 -> 323.61905
A9: =A8+1 -> 2 | B9: =$B$1+A9-1 -> 61 | C9: =_xlfn.XLOOKUP(B9,Mortality_Table!$A:$A,Mortality_Table!$B:$B) -> 0.003792 | D9: =1-C9 -> 0.996208 | E9: =E8*D8 -> 0.996602 | F9: =1/(1+$B$4)^A9 -> 0.90702948 | G9: =$B$2*E9*C9*F9 -> 342.77685
A10: =A9+1 -> 3 | B10: =$B$1+A10-1 -> 62 | C10: =_xlfn.XLOOKUP(B10,Mortality_Table!$A:$A,Mortality_Table!$B:$B) -> 0.004234 | D10: =1-C10 -> 0.995766 | E10: =E9*D9 -> 0.99282289 | F10: =1/(1+$B$4)^A10 -> 0.8638376 | G10: =$B$2*E10*C10*F10 -> 363.12382
A11: =A10+1 -> 4 | B11: =$B$1+A11-1 -> 63 | C11: =_xlfn.XLOOKUP(B11,Mortality_Table!$A:$A,Mortality_Table!$B:$B) -> 0.00473 | D11: =1-C11 -> 0.99527 | E11: =E10*D10 -> 0.98861927 | F11: =1/(1+$B$4)^A11 -> 0.82270247 | G11: =$B$2*E11*C11*F11 -> 384.70959
A12: =A11+1 -> 5 | B12: =$B$1+A12-1 -> 64 | C12: =_xlfn.XLOOKUP(B12,Mortality_Table!$A:$A,Mortality_Table!$B:$B) -> 0.005288 | D12: =1-C12 -> 0.994712 | E12: =E11*D11 -> 0.9839431 | F12: =1/(1+$B$4)^A12 -> 0.78352617 | G12: =$B$2*E12*C12*F12 -> 407.6758
A13: =A12+1 -> 6 | B13: =$B$1+A13-1 -> 65 | C13: =_xlfn.XLOOKUP(B13,Mortality_Table!$A:$A,Mortality_Table!$B:$B) -> 0.005915 | D13: =1-C13 -> 0.994085 | E13: =E12*D12 -> 0.97874001 | F13: =1/(1+$B$4)^A13 -> 0.7462154 | G13: =$B$2*E13*C13*F13 -> 432.00254
A14: =A13+1 -> 7 | B14: =$B$1+A14-1 -> 66 | C14: =_xlfn.XLOOKUP(B14,Mortality_Table!$A:$A,Mortality_Table!$B:$B) -> 0.006619 | D14: =1-C14 -> 0.993381 | E14: =E13*D13 -> 0.97295077 | F14: =1/(1+$B$4)^A14 -> 0.71068133 | G14: =$B$2*E14*C14*F14 -> 457.67601
A15: =A14+1 -> 8 | B15: =$B$1+A15-1 -> 67 | C15: =_xlfn.XLOOKUP(B15,Mortality_Table!$A:$A,Mortality_Table!$B:$B) -> 0.007409 | D15: =1-C15 -> 0.992591 | E15: =E14*D14 -> 0.9665108 | F15: =1/(1+$B$4)^A15 -> 0.67683936 | G15: =$B$2*E15*C15*F15 -> 484.67645
A16: =A15+1 -> 9 | B16: =$B$1+A16-1 -> 68 | C16: =_xlfn.XLOOKUP(B16,Mortality_Table!$A:$A,Mortality_Table!$B:$B) -> 0.008297 | D16: =1-C16 -> 0.991703 | E16: =E15*D15 -> 0.95934993 | F16: =1/(1+$B$4)^A16 -> 0.64460892 | G16: =$B$2*E16*C16*F16 -> 513.09106
A17: =A16+1 -> 10 | B17: =$B$1+A17-1 -> 69 | C17: =_xlfn.XLOOKUP(B17,Mortality_Table!$A:$A,Mortality_Table!$B:$B) -> 0.009294 | D17: =1-C17 -> 0.990706 | E17: =E16*D16 -> 0.9513902 | F17: =1/(1+$B$4)^A17 -> 0.61391325 | G17: =$B$2*E17*C17*F17 -> 542.83564
F19: Net Single Premium | G19: =SUM(G8:G17) -> 4252.1868
A21: Selected Issue Age | B21: 60
A22: Face Amount | B22: =inputs!B1 -> 100000
A23: Term | B23: =inputs!B2 -> 10
A24: Interest Rate | B24: =inputs!C3 -> 0.03
A27: Policy Year | B27: Attained Age | C27: qx | D27: px | E27: Survival to Start | F27: Discount Factor | G27: EPV Contribution
A28: 1 | B28: =$B$1+A28-1 -> 60 | C28: =_xlfn.XLOOKUP(B28,Mortality_Table!$A:$A,Mortality_Table!$B:$B) -> 0.003398 | D28: =1-C28 -> 0.996602 | E28: =1 -> 1 | F28: =1/(1+$B$24)^A28 -> 0.97087379 | G28: =$B$2*E28*C28*F28 -> 329.90291
A29: =A28+1 -> 2 | B29: =$B$1+A29-1 -> 61 | C29: =_xlfn.XLOOKUP(B29,Mortality_Table!$A:$A,Mortality_Table!$B:$B) -> 0.003792 | D29: =1-C29 -> 0.996208 | E29: =E28*D28 -> 0.996602 | F29: =1/(1+$B$24)^A29 -> 0.94259591 | G29: =$B$2*E29*C29*F29 -> 356.21781
A30: =A29+1 -> 3 | B30: =$B$1+A30-1 -> 62 | C30: =_xlfn.XLOOKUP(B30,Mortality_Table!$A:$A,Mortality_Table!$B:$B) -> 0.004234 | D30: =1-C30 -> 0.995766 | E30: =E29*D29 -> 0.99282289 | F30: =1/(1+$B$24)^A30 -> 0.91514166 | G30: =$B$2*E30*C30*F30 -> 384.69005
A31: =A30+1 -> 4 | B31: =$B$1+A31-1 -> 63 | C31: =_xlfn.XLOOKUP(B31,Mortality_Table!$A:$A,Mortality_Table!$B:$B) -> 0.00473 | D31: =1-C31 -> 0.99527 | E31: =E30*D30 -> 0.98861927 | F31: =1/(1+$B$24)^A31 -> 0.88848705 | G31: =$B$2*E31*C31*F31 -> 415.47157
A32: =A31+1 -> 5 | B32: =$B$1+A32-1 -> 64 | C32: =_xlfn.XLOOKUP(B32,Mortality_Table!$A:$A,Mortality_Table!$B:$B) -> 0.005288 | D32: =1-C32 -> 0.994712 | E32: =E31*D31 -> 0.9839431 | F32: =1/(1+$B$24)^A32 -> 0.86260878 | G32: =$B$2*E32*C32*F32 -> 448.82321
A33: =A32+1 -> 6 | B33: =$B$1+A33-1 -> 65 | C33: =_xlfn.XLOOKUP(B33,Mortality_Table!$A:$A,Mortality_Table!$B:$B) -> 0.005915 | D33: =1-C33 -> 0.994085 | E33: =E32*D32 -> 0.97874001 | F33: =1/(1+$B$24)^A33 -> 0.83748426 | G33: =$B$2*E33*C33*F33 -> 484.84034
A34: =A33+1 -> 7 | B34: =$B$1+A34-1 -> 66 | C34: =_xlfn.XLOOKUP(B34,Mortality_Table!$A:$A,Mortality_Table!$B:$B) -> 0.006619 | D34: =1-C34 -> 0.993381 | E34: =E33*D33 -> 0.97295077 | F34: =1/(1+$B$24)^A34 -> 0.81309151 | G34: =$B$2*E34*C34*F34 -> 523.62777
A35: =A34+1 -> 8 | B35: =$B$1+A35-1 -> 67 | C35: =_xlfn.XLOOKUP(B35,Mortality_Table!$A:$A,Mortality_Table!$B:$B) -> 0.007409 | D35: =1-C35 -> 0.992591 | E35: =E34*D34 -> 0.9665108 | F35: =1/(1+$B$24)^A35 -> 0.78940923 | G35: =$B$2*E35*C35*F35 -> 565.28637
A36: =A35+1 -> 9 | B36: =$B$1+A36-1 -> 68 | C36: =_xlfn.XLOOKUP(B36,Mortality_Table!$A:$A,Mortality_Table!$B:$B) -> 0.008297 | D36: =1-C36 -> 0.991703 | E36: =E35*D35 -> 0.95934993 | F36: =1/(1+$B$24)^A36 -> 0.76641673 | G36: =$B$2*E36*C36*F36 -> 610.04674
A37: =A36+1 -> 10 | B37: =$B$1+A37-1 -> 69 | C37: =_xlfn.XLOOKUP(B37,Mortality_Table!$A:$A,Mortality_Table!$B:$B) -> 0.009294 | D37: =1-C37 -> 0.990706 | E37: =E36*D36 -> 0.9513902 | F37: =1/(1+$B$24)^A37 -> 0.74409391 | G37: =$B$2*E37*C37*F37 -> 657.94425
F39: Net Single Premium | G39: =SUM(G28:G37) -> 4776.851
A42: Selected Issue Age | B42: 60
A43: Face Amount | B43: =inputs!B1 -> 100000
A44: Term | B44: =inputs!B2 -> 10
A45: Interest Rate | B45: =inputs!D3 -> 0.07
A48: Policy Year | B48: Attained Age | C48: qx | D48: px | E48: Survival to Start | F48: Discount Factor | G48: EPV Contribution
A49: 1 | B49: =$B$1+A49-1 -> 60 | C49: =_xlfn.XLOOKUP(B49,Mortality_Table!$A:$A,Mortality_Table!$B:$B) -> 0.003398 | D49: =1-C49 -> 0.996602 | E49: =1 -> 1 | F49: =1/(1+$B$45)^A49 -> 0.93457944 | G49: =$B$2*E49*C49*F49 -> 317.57009
A50: =A49+1 -> 2 | B50: =$B$1+A50-1 -> 61 | C50: =_xlfn.XLOOKUP(B50,Mortality_Table!$A:$A,Mortality_Table!$B:$B) -> 0.003792 | D50: =1-C50 -> 0.996208 | E50: =E49*D49 -> 0.996602 | F50: =1/(1+$B$45)^A50 -> 0.87343873 | G50: =$B$2*E50*C50*F50 -> 330.08252
A51: =A50+1 -> 3 | B51: =$B$1+A51-1 -> 62 | C51: =_xlfn.XLOOKUP(B51,Mortality_Table!$A:$A,Mortality_Table!$B:$B) -> 0.004234 | D51: =1-C51 -> 0.995766 | E51: =E50*D50 -> 0.99282289 | F51: =1/(1+$B$45)^A51 -> 0.81629788 | G51: =$B$2*E51*C51*F51 -> 343.13996
...

Sheet Summary
A1: Interest Rate | B1: =inputs!B3 -> 0.05
A2: Issue Age | B2: Net Single Premium
A3: 30 | B3: 295.15811
A4: 40 | B4: 573.09554
A5: 50 | B5: 1461.0406
A6: 60 | B6: 4252.1868
A25: Issue Age 60
A26: Interest Rate | B26: Net Single Premium
A27: 0.03 | B27: =Pricing!G39 -> 4776.851
A28: 0.05 | B28: =Pricing!G19 -> 4252.1868
A29: 0.07 | B29: =Pricing!G60 -> 3804.5386
